Workbook

Sheet Video Instructions
A1: What is the Industry Data Matrix:
A2: The Peer Comparison Matrix is an internal tool used to compare a customer's API metrics (like reuse rate and reusability) against those of similar customers. It helps provide context to the customer's data and understand how they're performing relative to their peers. The matrix contains data from about 190+ customers across different operating units. It's important to note that this spreadsheetis for internal use only and should never be shared with customers.
A4: Video Instructions

Sheet Input Tab
A1: Customer
A2: OU | C2: ⬅️ Please do not type here. Just pick from the drop down
A3: # APIs Total
A4: # APIs being consumed more than once
A5: # APIs being consumed only once
A6: # APIs as Batch or Zombie (no consumer)
A7: # Consumers
A8: # Reuse Instances
A9: % APIs with multiple Consumers
A10: % APIs with single Consumers
A11: % APIs without any Consumer
A12: % Reuse rate (over APIs with at least one consumer)
A13: % Reuse rate (over all APIs)
A14: # Reuse Index (over APIs with at least one consumer)
... A17: % Reusability

Sheet Peer Comparison
B1: Customer | C1: 31 - 60 APIs | E1: Number of Records used
B2: Aristocrat | C2: OU | D2: Retail/Consumer Goods | E2: =IFERROR(__xludf.DUMMYFUNCTION("IF(AND($D$2=""All"", $C$1=""All""), COUNTA('Data Tab'!C2:C1707), IF($D$2=""All"", COUNTIFS('Data Tab'!D2:D1707, "">="" & REGEXEXTRACT($C$1, ""^\d+""), 'Data Tab'!D2:D1707, ""<="" & IFERROR(REGEXEXTRACT($C$1, ""- (\d+)""), 999999)), IF($C$1=""All"", COUNTI"&"F('Data Tab'!C2:C1707, $D$2), COUNTIFS('Data Tab'!C2:C1707, $D$2, 'Data Tab'!D2:D1707, "">="" & REGEXEXTRACT($C$1, ""^\d+""), 'Data Tab'!D2:D1707, ""<="" & IFERROR(REGEXEXTRACT($C$1, ""- (\d+)""), 999999)))))"),27.0) -> 27
C3: API Size
A4: OU | B4: All
A5: # APIs Total | B5: {=IF($B$2="","", INDEX('Data Tab'!D:D, MATCH($B$2, 'Data Tab'!A:A, 0)))} -> 20 | D5: =IFERROR(__xludf.DUMMYFUNCTION("IFERROR(AVERAGE(FILTER('Data Tab'!D$2:D1707, 'Data Tab'!$A$2:$A1707<>"""", IF($D$2=""All"", 'Data Tab'!$A$2:$A1707<>"""", 'Data Tab'!$C$2:$C1707=$D$2), IF($C$1=""All"", 'Data Tab'!$A$2:$A1707<>"""", VLOOKUP('Data Tab'!$A$2:$A1707, 'Helper Lists'!$B:$C, 2,"&" FALSE)=$C$1))), ""--"")"),44.51851851851852) -> 44.518519
A6: # APIs being consumed more than once | B6: {=IF($B$2="","", INDEX('Data Tab'!E:E, MATCH($B$2, 'Data Tab'!A:A, 0)))} -> 0 | D6: =IFERROR(__xludf.DUMMYFUNCTION("IFERROR(AVERAGE(FILTER('Data Tab'!E$2:E1707, 'Data Tab'!$A$2:$A1707<>"""", IF($D$2=""All"", 'Data Tab'!$A$2:$A1707<>"""", 'Data Tab'!$C$2:$C1707=$D$2), IF($C$1=""All"", 'Data Tab'!$A$2:$A1707<>"""", VLOOKUP('Data Tab'!$A$2:$A1707, 'Helper Lists'!$B:$C, 2,"&" FALSE)=$C$1))), ""--"")"),12.777777777777779) -> 12.777778
A7: # APIs being consumed only once | B7: {=IF($B$2="","", INDEX('Data Tab'!F:F, MATCH($B$2, 'Data Tab'!A:A, 0)))} -> 5 | D7: =IFERROR(__xludf.DUMMYFUNCTION("IFERROR(AVERAGE(FILTER('Data Tab'!F$2:F1707, 'Data Tab'!$A$2:$A1707<>"""", IF($D$2=""All"", 'Data Tab'!$A$2:$A1707<>"""", 'Data Tab'!$C$2:$C1707=$D$2), IF($C$1=""All"", 'Data Tab'!$A$2:$A1707<>"""", VLOOKUP('Data Tab'!$A$2:$A1707, 'Helper Lists'!$B:$C, 2,"&" FALSE)=$C$1))), ""--"")"),16.823529411764707) -> 16.823529
A8: # APIs as Batch or Zombie (no consumer) | B8: {=IF($B$2="","", INDEX('Data Tab'!G:G, MATCH($B$2, 'Data Tab'!A:A, 0)))} -> 15 | D8: =IFERROR(__xludf.DUMMYFUNCTION("IFERROR(AVERAGE(FILTER('Data Tab'!G$2:G1707, 'Data Tab'!$A$2:$A1707<>"""", IF($D$2=""All"", 'Data Tab'!$A$2:$A1707<>"""", 'Data Tab'!$C$2:$C1707=$D$2), IF($C$1=""All"", 'Data Tab'!$A$2:$A1707<>"""", VLOOKUP('Data Tab'!$A$2:$A1707, 'Helper Lists'!$B:$C, 2,"&" FALSE)=$C$1))), ""--"")"),14.296296296296296) -> 14.296296
A9: # Consumers | B9: {=IF($B$2="","", INDEX('Data Tab'!H:H, MATCH($B$2, 'Data Tab'!A:A, 0)))} -> 5 | D9: =IFERROR(__xludf.DUMMYFUNCTION("IFERROR(AVERAGE(FILTER('Data Tab'!H$2:H1707, 'Data Tab'!$A$2:$A1707<>"""", IF($D$2=""All"", 'Data Tab'!$A$2:$A1707<>"""", 'Data Tab'!$C$2:$C1707=$D$2), IF($C$1=""All"", 'Data Tab'!$A$2:$A1707<>"""", VLOOKUP('Data Tab'!$A$2:$A1707, 'Helper Lists'!$B:$C, 2,"&" FALSE)=$C$1))), ""--"")"),68.07407407407408) -> 68.074074
A10: # Reuse Instances | B10: {=IF($B$2="","", INDEX('Data Tab'!I:I, MATCH($B$2, 'Data Tab'!A:A, 0)))} -> 0 | D10: =IFERROR(__xludf.DUMMYFUNCTION("IFERROR(AVERAGE(FILTER('Data Tab'!I$2:I1707, 'Data Tab'!$A$2:$A1707<>"""", IF($D$2=""All"", 'Data Tab'!$A$2:$A1707<>"""", 'Data Tab'!$C$2:$C1707=$D$2), IF($C$1=""All"", 'Data Tab'!$A$2:$A1707<>"""", VLOOKUP('Data Tab'!$A$2:$A1707, 'Helper Lists'!$B:$C, 2,"&" FALSE)=$C$1))), ""--"")"),37.851851851851855) -> 37.851852
A11: % APIs with multiple Consumers | B11: {=IF($B$2="","", INDEX('Data Tab'!J:J, MATCH($B$2, 'Data Tab'!A:A, 0)))} -> 0 | D11: =IFERROR(__xludf.DUMMYFUNCTION("IFERROR(AVERAGE(FILTER('Data Tab'!J$2:J1707, 'Data Tab'!$A$2:$A1707<>"""", IF($D$2=""All"", 'Data Tab'!$A$2:$A1707<>"""", 'Data Tab'!$C$2:$C1707=$D$2), IF($C$1=""All"", 'Data Tab'!$A$2:$A1707<>"""", VLOOKUP('Data Tab'!$A$2:$A1707, 'Helper Lists'!$B:$C, 2,"&" FALSE)=$C$1))), ""--"")"),0.31174705882352943) -> 0.31174706
A12: % APIs with single Consumers | B12: {=IF($B$2="","", INDEX('Data Tab'!K:K, MATCH($B$2, 'Data Tab'!A:A, 0)))} -> 0.25 | D12: =IFERROR(__xludf.DUMMYFUNCTION("IFERROR(AVERAGE(FILTER('Data Tab'!K$2:K1707, 'Data Tab'!$A$2:$A1707<>"""", IF($D$2=""All"", 'Data Tab'!$A$2:$A1707<>"""", 'Data Tab'!$C$2:$C1707=$D$2), IF($C$1=""All"", 'Data Tab'!$A$2:$A1707<>"""", VLOOKUP('Data Tab'!$A$2:$A1707, 'Helper Lists'!$B:$C, 2,"&" FALSE)=$C$1))), ""--"")"),0.3920470588235294) -> 0.39204706
A13: % APIs without any Consumer | B13: {=IF($B$2="","", INDEX('Data Tab'!L:L, MATCH($B$2, 'Data Tab'!A:A, 0)))} -> 0.75 | D13: =IFERROR(__xludf.DUMMYFUNCTION("IFERROR(AVERAGE(FILTER('Data Tab'!L$2:L1707, 'Data Tab'!$A$2:$A1707<>"""", IF($D$2=""All"", 'Data Tab'!$A$2:$A1707<>"""", 'Data Tab'!$C$2:$C1707=$D$2), IF($C$1=""All"", 'Data Tab'!$A$2:$A1707<>"""", VLOOKUP('Data Tab'!$A$2:$A1707, 'Helper Lists'!$B:$C, 2,"&" FALSE)=$C$1))), ""--"")"),0.29622352941176466) -> 0.29622353
A14: % Reuse rate (over all APIs) | B14: {=IF($B$2="","", INDEX('Data Tab'!N:N, MATCH($B$2, 'Data Tab'!A:A, 0)))} -> 0 | D14: =IFERROR(__xludf.DUMMYFUNCTION("IFERROR(AVERAGE(FILTER('Data Tab'!N$2:N1707, 'Data Tab'!$A$2:$A1707<>"""", IF($D$2=""All"", 'Data Tab'!$A$2:$A1707<>"""", 'Data Tab'!$C$2:$C1707=$D$2), IF($C$1=""All"", 'Data Tab'!$A$2:$A1707<>"""", VLOOKUP('Data Tab'!$A$2:$A1707, 'Helper Lists'!$B:$C, 2,"&" FALSE)=$C$1))), ""--"")"),0.4487008072171733) -> 0.44870081
A15: # Reuse Index (over APIs with at least one consumer) | B15: {=IF($B$2="","", INDEX('Data Tab'!O:O, MATCH($B$2, 'Data Tab'!A:A, 0)))} -> 1 | D15: =IFERROR(__xludf.DUMMYFUNCTION("IFERROR(AVERAGE(FILTER('Data Tab'!O$2:O1707, 'Data Tab'!$A$2:$A1707<>"""", IF($D$2=""All"", 'Data Tab'!$A$2:$A1707<>"""", 'Data Tab'!$C$2:$C1707=$D$2), IF($C$1=""All"", 'Data Tab'!$A$2:$A1707<>"""", VLOOKUP('Data Tab'!$A$2:$A1707, 'Helper Lists'!$B:$C, 2,"&" FALSE)=$C$1))), ""--"")"),2.2227923982392577) -> 2.2227924
A16: # Reuse Index (over all APIs) | B16: {=IF($B$2="","", INDEX('Data Tab'!P:P, MATCH($B$2, 'Data Tab'!A:A, 0)))} -> 0.25 | D16: =IFERROR(__xludf.DUMMYFUNCTION("IFERROR(AVERAGE(FILTER('Data Tab'!P$2:P1707, 'Data Tab'!$A$2:$A1707<>"""", IF($D$2=""All"", 'Data Tab'!$A$2:$A1707<>"""", 'Data Tab'!$C$2:$C1707=$D$2), IF($C$1=""All"", 'Data Tab'!$A$2:$A1707<>"""", VLOOKUP('Data Tab'!$A$2:$A1707, 'Helper Lists'!$B:$C, 2,"&" FALSE)=$C$1))), ""--"")"),1.5994433902593295) -> 1.5994434
A17: % API-Led | B17: {=IF($B$2="","", INDEX('Data Tab'!Q:Q, MATCH($B$2, 'Data Tab'!A:A, 0)))} -> 0.25 | D17: =IFERROR(__xludf.DUMMYFUNCTION("IFERROR(IF(AND($D$2=""All"", $C$1=""All""), AVERAGE('Data Tab'!Q:Q), IF($D$2=""All"", AVERAGEIFS('Data Tab'!Q:Q, 'Data Tab'!D:D, "">="" & REGEXEXTRACT($C$1, ""^\d+""), 'Data Tab'!D:D, ""<="" & IFERROR(REGEXEXTRACT($C$1, ""- (\d+)""), 999999)), IF($C$1=""A"&"ll"", AVERAGEIF('Data Tab'!C:C, $D$2, 'Data Tab'!Q:Q), AVERAGEIFS('Data Tab'!Q:Q, 'Data Tab'!C:C, $D$2, 'Data Tab'!D:D, "">="" & REGEXEXTRACT($C$1, ""^\d+""), 'Data Tab'!D:D, ""<="" & IFERROR(REGEXEXTRACT($C$1, ""- (\d+)""), 999999))))), ""-"")"),0.6886172894084034) -> 0.68861729
A18: % Reuse rate (over APIs with at least one consumer) | B18: {=IF($B$2="","", INDEX('Data Tab'!M:M, MATCH($B$2, 'Data Tab'!A:A, 0)))} | D18: =IFERROR(__xludf.DUMMYFUNCTION("IFERROR(IF(AND($D$2=""All"", $C$1=""All""), AVERAGE('Data Tab'!M:M), IF($D$2=""All"", AVERAGEIFS('Data Tab'!M:M, 'Data Tab'!D:D, "">="" & REGEXEXTRACT($C$1, ""^\d+""), 'Data Tab'!D:D, ""<="" & IFERROR(REGEXEXTRACT($C$1, ""- (\d+)""), 999999)), IF($C$1=""A"&"ll"", AVERAGEIF('Data Tab'!C:C, $D$2, 'Data Tab'!M:M), AVERAGEIFS('Data Tab'!M:M, 'Data Tab'!C:C, $D$2, 'Data Tab'!D:D, "">="" & REGEXEXTRACT($C$1, ""^\d+""), 'Data Tab'!D:D, ""<="" & IFERROR(REGEXEXTRACT($C$1, ""- (\d+)""), 999999))))), ""-"")"),0.4992181995456214) -> 0.4992182
A19: % Reusability | B19: {=IF($B$2="","", INDEX('Data Tab'!R:R, MATCH($B$2, 'Data Tab'!A:A, 0)))} -> 0 | D19: =IFERROR(__xludf.DUMMYFUNCTION("IFERROR(IF(AND($D$2=""All"", $C$1=""All""), AVERAGE('Data Tab'!R:R), IF($D$2=""All"", AVERAGEIFS('Data Tab'!R:R, 'Data Tab'!D:D, "">="" & REGEXEXTRACT($C$1, ""^\d+""), 'Data Tab'!D:D, ""<="" & IFERROR(REGEXEXTRACT($C$1, ""- (\d+)""), 999999)), IF($C$1=""A"&"ll"", AVERAGEIF('Data Tab'!C:C, $D$2, 'Data Tab'!R:R), AVERAGEIFS('Data Tab'!R:R, 'Data Tab'!C:C, $D$2, 'Data Tab'!D:D, "">="" & REGEXEXTRACT($C$1, ""^\d+""), 'Data Tab'!D:D, ""<="" & IFERROR(REGEXEXTRACT($C$1, ""- (\d+)""), 999999))))), ""-"")"),0.41669885580207644) -> 0.41669886
A27: Peer Data Displayed
A28: Customer Name | B28: Number of APIs | C28: % Reuse rate (over APIs with at least one consumer) | D28: # Reuse Index (over APIs with at least one consumer) | E28: % API-Led | F28: % Reusability | G28: Col
A29: =IFERROR(__xludf.DUMMYFUNCTION("IFERROR(FILTER('Data Tab'!A2:A1707, ('Data Tab'!C2:C1707 = IF($D$2=""All"", 'Data Tab'!C2:C1707, $D$2)), IF($C$1=""All"", ROW('Data Tab'!A2:A1707)>0, IFERROR(VLOOKUP('Data Tab'!A2:A1707, 'Helper Lists'!B:C, 2, FALSE)) = $C$1)), """")"),"Red Lobster") -> Red Lobster | B29: =IFERROR(__xludf.DUMMYFUNCTION("IFERROR(FILTER('Data Tab'!D2:D1707, ('Data Tab'!C2:C1707 = IF($D$2=""All"", 'Data Tab'!C2:C1707, $D$2)), IF($C$1=""All"", ROW('Data Tab'!A2:A1707)>0, IFERROR(VLOOKUP('Data Tab'!A2:A1707, 'Helper Lists'!B:C, 2, FALSE)) = $C$1)), """")"),42.0) -> 42 | C29: =IFERROR(__xludf.DUMMYFUNCTION("IFERROR(FILTER('Data Tab'!M2:M1707, ('Data Tab'!C2:C1707 = IF($D$2=""All"", 'Data Tab'!C2:C1707, $D$2)), IF($C$1=""All"", ROW('Data Tab'!A2:A1707)>0, IFERROR(VLOOKUP('Data Tab'!A2:A1707, 'Helper Lists'!B:C, 2, FALSE)) = $C$1)), """")"),0.711) -> 0.711 | D29: =IFERROR(__xludf.DUMMYFUNCTION("IFERROR(FILTER('Data Tab'!O2:O1707, ('Data Tab'!C2:C1707 = IF($D$2=""All"", 'Data Tab'!C2:C1707, $D$2)), IF($C$1=""All"", ROW('Data Tab'!A2:A1707)>0, IFERROR(VLOOKUP('Data Tab'!A2:A1707, 'Helper Lists'!B:C, 2, FALSE)) = $C$1)), """")"),4.1) -> 4.1 | E29: =IFERROR(__xludf.DUMMYFUNCTION("IFERROR(FILTER('Data Tab'!Q2:Q1707, ('Data Tab'!C2:C1707 = IF($D$2=""All"", 'Data Tab'!C2:C1707, $D$2)), IF($C$1=""All"", ROW('Data Tab'!A2:A1707)>0, IFERROR(VLOOKUP('Data Tab'!A2:A1707, 'Helper Lists'!B:C, 2, FALSE)) = $C$1)), """")"),0.7143) -> 0.7143 | F29: =IFERROR(__xludf.DUMMYFUNCTION("IFERROR(FILTER('Data Tab'!R2:R1707, ('Data Tab'!C2:C1707 = IF($D$2=""All"", 'Data Tab'!C2:C1707, $D$2)), IF($C$1=""All"", ROW('Data Tab'!A2:A1707)>0, IFERROR(VLOOKUP('Data Tab'!A2:A1707, 'Helper Lists'!B:C, 2, FALSE)) = $C$1)), """")"),0.4667) -> 0.4667 | G29: {=IF(LEN(B29:B1707)>1,1,"")} -> 1
A30: =IFERROR(__xludf.DUMMYFUNCTION("""COMPUTED_VALUE"""),"Yum! Brands") -> Yum! Brands | B30: =IFERROR(__xludf.DUMMYFUNCTION("""COMPUTED_VALUE"""),48.0) -> 48 | C30: =IFERROR(__xludf.DUMMYFUNCTION("""COMPUTED_VALUE"""),0.55) -> 0.55 | D30: =IFERROR(__xludf.DUMMYFUNCTION("""COMPUTED_VALUE"""),2.22) -> 2.22 | E30: =IFERROR(__xludf.DUMMYFUNCTION("""COMPUTED_VALUE"""),0.75) -> 0.75 | F30: =IFERROR(__xludf.DUMMYFUNCTION("""COMPUTED_VALUE"""),0.44439999999999996) -> 0.4444 | G30: 1
A31: =IFERROR(__xludf.DUMMYFUNCTION("""COMPUTED_VALUE"""),"saks") -> saks | B31: =IFERROR(__xludf.DUMMYFUNCTION("""COMPUTED_VALUE"""),47.0) -> 47 | C31: =IFERROR(__xludf.DUMMYFUNCTION("""COMPUTED_VALUE"""),0.653) -> 0.653 | D31: =IFERROR(__xludf.DUMMYFUNCTION("""COMPUTED_VALUE"""),2.32) -> 2.32 | E31: =IFERROR(__xludf.DUMMYFUNCTION("""COMPUTED_VALUE"""),0.7234) -> 0.7234 | F31: =IFERROR(__xludf.DUMMYFUNCTION("""COMPUTED_VALUE"""),0.2353) -> 0.2353 | G31: 1
A32: =IFERROR(__xludf.DUMMYFUNCTION("""COMPUTED_VALUE"""),"Weis Markets") -> Weis Markets | B32: =IFERROR(__xludf.DUMMYFUNCTION("""COMPUTED_VALUE"""),31.0) -> 31 | C32: =IFERROR(__xludf.DUMMYFUNCTION("""COMPUTED_VALUE"""),0.5217) -> 0.5217 | D32: =IFERROR(__xludf.DUMMYFUNCTION("""COMPUTED_VALUE"""),2.09090909090909) -> 2.0909091 | E32: =IFERROR(__xludf.DUMMYFUNCTION("""COMPUTED_VALUE"""),0.7097) -> 0.7097 | F32: =IFERROR(__xludf.DUMMYFUNCTION("""COMPUTED_VALUE"""),0.5455) -> 0.5455 | G32: 1
A33: =IFERROR(__xludf.DUMMYFUNCTION("""COMPUTED_VALUE"""),"Hot Topic") -> Hot Topic | B33: =IFERROR(__xludf.DUMMYFUNCTION("""COMPUTED_VALUE"""),49.0) -> 49 | C33: =IFERROR(__xludf.DUMMYFUNCTION("""COMPUTED_VALUE"""),0.4783) -> 0.4783 | D33: =IFERROR(__xludf.DUMMYFUNCTION("""COMPUTED_VALUE"""),1.92) -> 1.92 | E33: =IFERROR(__xludf.DUMMYFUNCTION("""COMPUTED_VALUE"""),0.24489999999999998) -> 0.2449 | F33: =IFERROR(__xludf.DUMMYFUNCTION("""COMPUTED_VALUE"""),0.5) -> 0.5 | G33: 1
A34: =IFERROR(__xludf.DUMMYFUNCTION("""COMPUTED_VALUE"""),"BATA Brands") -> BATA Brands | B34: =IFERROR(__xludf.DUMMYFUNCTION("""COMPUTED_VALUE"""),51.0) -> 51 | C34: =IFERROR(__xludf.DUMMYFUNCTION("""COMPUTED_VALUE"""),0.6666666666666666) -> 0.66666667 | D34: =IFERROR(__xludf.DUMMYFUNCTION("""COMPUTED_VALUE"""),3.0) -> 3 | E34: =IFERROR(__xludf.DUMMYFUNCTION("""COMPUTED_VALUE"""),0.8627450980392157) -> 0.8627451 | F34: =IFERROR(__xludf.DUMMYFUNCTION("""COMPUTED_VALUE"""),0.5227272727272727) -> 0.52272727 | G34: 1
A35: =IFERROR(__xludf.DUMMYFUNCTION("""COMPUTED_VALUE"""),"Calzedonia SPA") -> Calzedonia SPA | B35: =IFERROR(__xludf.DUMMYFUNCTION("""COMPUTED_VALUE"""),36.0) -> 36 | C35: =IFERROR(__xludf.DUMMYFUNCTION("""COMPUTED_VALUE"""),0.6376811594202898) -> 0.63768116 | D35: =IFERROR(__xludf.DUMMYFUNCTION("""COMPUTED_VALUE"""),2.76) -> 2.76 | E35: =IFERROR(__xludf.DUMMYFUNCTION("""COMPUTED_VALUE"""),0.6944444444444444) -> 0.69444444 | F35: =IFERROR(__xludf.DUMMYFUNCTION("""COMPUTED_VALUE"""),0.44) -> 0.44 | G35: 1
A36: =IFERROR(__xludf.DUMMYFUNCTION("""COMPUTED_VALUE"""),"Damm SA") -> Damm SA | B36: =IFERROR(__xludf.DUMMYFUNCTION("""COMPUTED_VALUE"""),37.0) -> 37 | C36: =IFERROR(__xludf.DUMMYFUNCTION("""COMPUTED_VALUE"""),0.4358974358974359) -> 0.43589744 | D36: =IFERROR(__xludf.DUMMYFUNCTION("""COMPUTED_VALUE"""),1.7727272727272727) -> 1.7727273 | E36: =IFERROR(__xludf.DUMMYFUNCTION("""COMPUTED_VALUE"""),0.5945945945945946) -> 0.59459459 | F36: =IFERROR(__xludf.DUMMYFUNCTION("""COMPUTED_VALUE"""),0.4090909090909091) -> 0.40909091 | G36: 1
A37: =IFERROR(__xludf.DUMMYFUNCTION("""COMPUTED_VALUE"""),"Hunkemöller BV") -> Hunkemöller BV | B37: =IFERROR(__xludf.DUMMYFUNCTION("""COMPUTED_VALUE"""),36.0) -> 36 | C37: =IFERROR(__xludf.DUMMYFUNCTION("""COMPUTED_VALUE"""),0.5151515151515151) -> 0.51515152 | D37: =IFERROR(__xludf.DUMMYFUNCTION("""COMPUTED_VALUE"""),2.0625) -> 2.0625 | E37: =IFERROR(__xludf.DUMMYFUNCTION("""COMPUTED_VALUE"""),0.8888888888888888) -> 0.88888889 | F37: =IFERROR(__xludf.DUMMYFUNCTION("""COMPUTED_VALUE"""),0.5) -> 0.5 | G37: 1
A38: =IFERROR(__xludf.DUMMYFUNCTION("""COMPUTED_VALUE"""),"Mars") -> Mars | B38: =IFERROR(__xludf.DUMMYFUNCTION("""COMPUTED_VALUE"""),60.0) -> 60 | C38: =IFERROR(__xludf.DUMMYFUNCTION("""COMPUTED_VALUE"""),0.3620689655172414) -> 0.36206897 | D38: =IFERROR(__xludf.DUMMYFUNCTION("""COMPUTED_VALUE"""),1.5675675675675675) -> 1.5675676 | E38: =IFERROR(__xludf.DUMMYFUNCTION("""COMPUTED_VALUE"""),0.6166666666666667) -> 0.61666667 | F38: =IFERROR(__xludf.DUMMYFUNCTION("""COMPUTED_VALUE"""),0.4594594594594595) -> 0.45945946 | G38: 1
A39: =IFERROR(__xludf.DUMMYFUNCTION("""COMPUTED_VALUE"""),"Newell Brands") -> Newell Brands | B39: =IFERROR(__xludf.DUMMYFUNCTION("""COMPUTED_VALUE"""),47.0) -> 47 | C39: =IFERROR(__xludf.DUMMYFUNCTION("""COMPUTED_VALUE"""),0.7604166666666666) -> 0.76041667 | D39: =IFERROR(__xludf.DUMMYFUNCTION("""COMPUTED_VALUE"""),4.173913043478261) -> 4.173913 | E39: =IFERROR(__xludf.DUMMYFUNCTION("""COMPUTED_VALUE"""),0.48936170212765956) -> 0.4893617 | F39: =IFERROR(__xludf.DUMMYFUNCTION("""COMPUTED_VALUE"""),0.5652173913043478) -> 0.56521739 | G39: 1
A40: =IFERROR(__xludf.DUMMYFUNCTION("""COMPUTED_VALUE"""),"Panera LLC") -> Panera LLC | B40: =IFERROR(__xludf.DUMMYFUNCTION("""COMPUTED_VALUE"""),52.0) -> 52 | C40: =IFERROR(__xludf.DUMMYFUNCTION("""COMPUTED_VALUE"""),0.3023255813953488) -> 0.30232558 | D40: =IFERROR(__xludf.DUMMYFUNCTION("""COMPUTED_VALUE"""),1.4333333333333333) -> 1.4333333 | E40: =IFERROR(__xludf.DUMMYFUNCTION("""COMPUTED_VALUE"""),0.5769230769230769) -> 0.57692308 | F40: =IFERROR(__xludf.DUMMYFUNCTION("""COMPUTED_VALUE"""),0.16666666666666666) -> 0.16666667 | G40: 1
A41: =IFERROR(__xludf.DUMMYFUNCTION("""COMPUTED_VALUE"""),"Punto Fa S.L. - Mango") -> Punto Fa S.L. - Mango | B41: =IFERROR(__xludf.DUMMYFUNCTION("""COMPUTED_VALUE"""),60.0) -> 60 | C41: =IFERROR(__xludf.DUMMYFUNCTION("""COMPUTED_VALUE"""),0.21568627450980393) -> 0.21568627 | D41: =IFERROR(__xludf.DUMMYFUNCTION("""COMPUTED_VALUE"""),1.275) -> 1.275 | E41: =IFERROR(__xludf.DUMMYFUNCTION("""COMPUTED_VALUE"""),0.6666666666666666) -> 0.66666667 | F41: =IFERROR(__xludf.DUMMYFUNCTION("""COMPUTED_VALUE"""),0.175) -> 0.175 | G41: 1
A42: =IFERROR(__xludf.DUMMYFUNCTION("""COMPUTED_VALUE"""),"Safelite Group, Inc") -> Safelite Group, Inc | B42: =IFERROR(__xludf.DUMMYFUNCTION("""COMPUTED_VALUE"""),37.0) -> 37 | C42: =IFERROR(__xludf.DUMMYFUNCTION("""COMPUTED_VALUE"""),0.32432432432432434) -> 0.32432432 | D42: =IFERROR(__xludf.DUMMYFUNCTION("""COMPUTED_VALUE"""),1.48) -> 1.48 | E42: =IFERROR(__xludf.DUMMYFUNCTION("""COMPUTED_VALUE"""),0.6756756756756757) -> 0.67567568 | F42: =IFERROR(__xludf.DUMMYFUNCTION("""COMPUTED_VALUE"""),0.32) -> 0.32 | G42: 1
A43: =IFERROR(__xludf.DUMMYFUNCTION("""COMPUTED_VALUE"""),"SMCP_HQ") -> SMCP_HQ | B43: =IFERROR(__xludf.DUMMYFUNCTION("""COMPUTED_VALUE"""),48.0) -> 48 | C43: =IFERROR(__xludf.DUMMYFUNCTION("""COMPUTED_VALUE"""),0.625) -> 0.625 | D43: =IFERROR(__xludf.DUMMYFUNCTION("""COMPUTED_VALUE"""),2.6666666666666665) -> 2.6666667 | E43: =IFERROR(__xludf.DUMMYFUNCTION("""COMPUTED_VALUE"""),0.5625) -> 0.5625 | F43: =IFERROR(__xludf.DUMMYFUNCTION("""COMPUTED_VALUE"""),0.4074074074074074) -> 0.40740741 | G43: 1
A44: =IFERROR(__xludf.DUMMYFUNCTION("""COMPUTED_VALUE"""),"MECCA") -> MECCA | B44: =IFERROR(__xludf.DUMMYFUNCTION("""COMPUTED_VALUE"""),57.0) -> 57 | C44: =IFERROR(__xludf.DUMMYFUNCTION("""COMPUTED_VALUE"""),0.5207999999999999) -> 0.5208 | D44: =IFERROR(__xludf.DUMMYFUNCTION("""COMPUTED_VALUE"""),2.09) -> 2.09 | E44: =IFERROR(__xludf.DUMMYFUNCTION("""COMPUTED_VALUE"""),0.4035) -> 0.4035 | F44: =IFERROR(__xludf.DUMMYFUNCTION("""COMPUTED_VALUE"""),0.3478) -> 0.3478 | G44: 1
A45: =IFERROR(__xludf.DUMMYFUNCTION("""COMPUTED_VALUE"""),"7-Eleven (Australia)") -> 7-Eleven (Australia) | B45: =IFERROR(__xludf.DUMMYFUNCTION("""COMPUTED_VALUE"""),43.0) -> 43 | C45: =IFERROR(__xludf.DUMMYFUNCTION("""COMPUTED_VALUE"""),0.5) -> 0.5 | D45: =IFERROR(__xludf.DUMMYFUNCTION("""COMPUTED_VALUE"""),2.0) -> 2 | E45: =IFERROR(__xludf.DUMMYFUNCTION("""COMPUTED_VALUE"""),0.8371999999999999) -> 0.8372 | F45: =IFERROR(__xludf.DUMMYFUNCTION("""COMPUTED_VALUE"""),0.4167) -> 0.4167 | G45: 1
A46: =IFERROR(__xludf.DUMMYFUNCTION("""COMPUTED_VALUE"""),"The Clorox Company") -> The Clorox Company | B46: =IFERROR(__xludf.DUMMYFUNCTION("""COMPUTED_VALUE"""),45.0) -> 45 | C46: =IFERROR(__xludf.DUMMYFUNCTION("""COMPUTED_VALUE"""),0.3846) -> 0.3846 | D46: =IFERROR(__xludf.DUMMYFUNCTION("""COMPUTED_VALUE"""),1.625) -> 1.625 | E46: =IFERROR(__xludf.DUMMYFUNCTION("""COMPUTED_VALUE"""),0.5333) -> 0.5333 | F46: =IFERROR(__xludf.DUMMYFUNCTION("""COMPUTED_VALUE"""),0.1667) -> 0.1667 | G46: 1
A47: =IFERROR(__xludf.DUMMYFUNCTION("""COMPUTED_VALUE"""),"Casey's General Stores") -> Casey's General Stores | B47: =IFERROR(__xludf.DUMMYFUNCTION("""COMPUTED_VALUE"""),51.0) -> 51 | C47: =IFERROR(__xludf.DUMMYFUNCTION("""COMPUTED_VALUE"""),0.7423000000000001) -> 0.7423 | D47: =IFERROR(__xludf.DUMMYFUNCTION("""COMPUTED_VALUE"""),3.88) -> 3.88 | E47: =IFERROR(__xludf.DUMMYFUNCTION("""COMPUTED_VALUE"""),0.8234999999999999) -> 0.8235 | F47: =IFERROR(__xludf.DUMMYFUNCTION("""COMPUTED_VALUE"""),0.7857) -> 0.7857 | G47: 1
...

Sheet Data Tab
A1: Customer | B1: Account ID | C1: OU | D1: # APIs Total | E1: # APIs being consumed more than once | F1: # APIs being consumed only once | G1: # APIs as Batch or Zombie (no consumer) | H1: # Consumers | I1: # Reuse Instances | J1: % APIs with multiple Consumers | K1: % APIs with single Consumers | L1: % APIs without any Consumer | M1: % Reuse rate (over APIs with at least one consumer) | N1: % Reuse rate (over all APIs) | O1: # Reuse Index (over APIs with at least one consumer) | P1: # Reuse Index (over all APIs) | Q1: % API-Led | R1: % Reusability | S1: Date Generated
A2: Stellantis Financial Services | B2: 0013000000FI20DAAT | C2: Manufacturing, Auto, Energy | D2: 41 | E2: 12 | F2: 26 | G2: 3 | H2: 67 | I2: 29 | J2: 0.2927 | K2: 0.6341 | L2: 0.0732 | M2: 0.4328 | O2: 1.76 | P2: 1.63 | Q2: 0.9268 | R2: 0.3158
A3: SAUR | B3: 0013y00001cSxloAAC | C3: Manufacturing, Auto, Energy | D3: 65 | E3: 39 | F3: 21 | G3: 5 | H3: 143 | I3: 83 | J3: 0.6 | K3: 0.3231 | L3: 0.0769 | M3: 0.5 | N3: 0.5804 | O3: 2.38 | P3: 2.2 | Q3: 0.9231 | R3: 0.65
A4: MVW | C4: Consumer and Business Services | D4: 55 | E4: 19 | F4: 31 | G4: 5 | H4: 120 | I4: 70 | J4: 0.3455 | K4: 0.5636 | L4: 0.0909 | M4: 0.5833 | N4: -- | O4: 2.4 | P4: 2.1818182 | Q4: 0.9091 | R4: 0.38
A5: Driscoll's | B5: 0013000001GVTDZAA5 | C5: Retail/Consumer Goods | D5: 122 | E5: 76 | F5: 34 | G5: 12 | H5: 364 | I5: 254 | J5: 0.623 | K5: 0.2787 | L5: 0.0984 | M5: 0.6978 | N5: -- | O5: 3.3090909 | P5: 2.9836066 | Q5: 0.9016 | R5: 0.6909
A6: Red Lobster | B6: 0013000001L69bcAAB | C6: Retail/Consumer Goods | D6: 42 | E6: 14 | F6: 16 | G6: 12 | H6: 123 | I6: 93 | J6: 0.3333 | K6: 0.381 | L6: 0.2857 | M6: 0.711 | N6: 0.7561 | O6: 4.1 | P6: 2.93 | Q6: 0.7143 | R6: 0.4667
A7: Coast Capital Savings | B7: 0013000000M1wn8AAB | C7: Financial Services & Insurance | D7: 135 | E7: 44 | F7: 74 | G7: 17 | H7: 219 | I7: 101 | J7: 0.3259 | K7: 0.5481 | L7: 0.1259 | M7: 0.4612 | N7: -- | O7: 1.8559322 | P7: 1.6222222 | Q7: 0.8741 | R7: 0.3729
A8: Fairview Health Services | B8: 0010M00001NYh7zQAD | C8: Healthcare, Life Sciences | D8: 64 | E8: 19 | F8: 32 | G8: 13 | H8: 120 | I8: 69 | J8: 0.2969 | K8: 0.5 | L8: 0.2031 | M8: 0.6154 | N8: 0.575 | O8: 2.35 | P8: 1.88 | Q8: 0.7969 | R8: 0.3725
A9: Arise Virtual Solutions | B9: 0013000000IW9AoAAL | C9: Consumer and Business Services | D9: 13 | E9: 7 | F9: 4 | G9: 2 | H9: 29 | I9: 18 | J9: 0.5385 | K9: 0.3077 | L9: 0.1538 | M9: 0.6207 | N9: -- | O9: 2.6363636 | P9: 2.2307692 | Q9: 0.8462 | R9: 0.6364
A10: Panduit | B10: 0013000000M1ZebAAF | C10: Manufacturing, Auto, Energy | D10: 30 | E10: 12 | F10: 13 | G10: 5 | H10: 61 | I10: 36 | J10: 0.4 | K10: 0.4333 | L10: 0.1667 | M10: 0.5902 | O10: 2.44 | P10: 2.03 | Q10: 0.8333 | R10: 0.48
A11: 3M Company | B11: 00100000002IdvWAAS | C11: Manufacturing, Auto, Energy | D11: 95 | E11: 18 | F11: 61 | G11: 16 | H11: 175 | I11: 96 | J11: 0.1895 | K11: 0.6421 | L11: 0.1684 | M11: 0.5486 | N11: -- | O11: 2.2151899 | P11: 1.8421053 | Q11: 0.8316 | R11: 0.2278
A12: COSTA CROCIERE SPA | B12: 00130000002xIIIAA2 | C12: Travel, Transportation, & Hospitality | D12: 23 | E12: 11 | F12: 8 | G12: 4 | H12: 54 | I12: 35 | J12: 0.4783 | K12: 0.3478 | L12: 0.1739 | M12: 0.6481 | N12: -- | O12: 2.8421053 | P12: 2.3478261 | Q12: 0.8261 | R12: 0.5789
A13: Texas Health Resources | B13: 00130000002xcqWAAQ | C13: Healthcare, Life Sciences | D13: 72 | E13: 9 | F13: 50 | G13: 13 | H13: 75 | I13: 16 | J13: 0.125 | K13: 0.6944 | L13: 0.1806 | M13: 0.2133 | N13: -- | O13: 1.2711864 | P13: 1.0416667 | Q13: 0.8194 | R13: 0.1525
A14: Landstar | B14: 0013y00001bdbMLAAY | C14: Consumer and Business Services | D14: 115 | E14: 44 | F14: 47 | G14: 24 | H14: 255 | I14: 164 | J14: 0.3826 | K14: 0.4087 | L14: 0.2087 | M14: 0.6431 | O14: 2.8 | P14: 2.22 | Q14: 0.7913 | R14: 0.4835
A15: AAA Automobile Club of Southern California | B15: 0013000000RYuIfAAL | C15: Financial Services & Insurance | D15: 250 | E15: 82 | F15: 115 | G15: 53 | H15: 638 | I15: 441 | J15: 0.328 | K15: 0.46 | L15: 0.212 | M15: 0.6912 | N15: -- | O15: 3.2385787 | P15: 2.552 | Q15: 0.788 | R15: 0.4162
A16: Pentagon Federal Credit Union | B16: 0010M00001JzikWQAR | C16: Financial Services & Insurance | D16: 158 | E16: 56 | F16: 68 | G16: 34 | H16: 314 | I16: 190 | J16: 0.3544 | K16: 0.4304 | L16: 0.2152 | M16: 0.4333 | N16: 0.6051 | O16: 2.53 | P16: 1.99 | Q16: 0.7848 | R16: 0.4516
A17: General Mills | B17: 0013y00001cQ3EtAAK | C17: Retail/Consumer Goods | D17: 27 | E17: 14 | F17: 7 | G17: 6 | H17: 49 | I17: 28 | J17: 0.5185 | K17: 0.2593 | L17: 0.2222 | M17: 0.5714 | N17: -- | O17: 2.3333333 | P17: 1.8148148 | Q17: 0.7778 | R17: 0.6667
A18: Dolce & Gabbana | B18: 0013000000HI6oVAAT | C18: Retail/Consumer Goods | D18: 76 | E18: 25 | F18: 34 | G18: 17 | H18: 117 | I18: 58 | J18: 0.3289 | K18: 0.4474 | L18: 0.2237 | M18: 0.4957 | N18: -- | O18: 1.98 | P18: 1.54 | Q18: 0.7763 | R18: 0.4237
A19: Builders FirstSource | B19: 00130000000MLvaAAG | C19: Consumer and Business Services | D19: 42 | E19: 7 | F19: 25 | G19: 10 | H19: 42 | I19: 10 | J19: 0.1667 | K19: 0.5952 | L19: 0.2381 | M19: 0.2381 | N19: -- | O19: 1.31 | P19: 1 | Q19: 0.7619 | R19: 0.2188
A20: Yum! Brands | C20: Retail/Consumer Goods | D20: 48 | E20: 16 | F20: 20 | G20: 12 | H20: 80 | I20: 44 | J20: 0.3333 | K20: 0.4167 | L20: 0.25 | M20: 0.55 | N20: -- | O20: 2.22 | P20: 1.67 | Q20: 0.75 | R20: 0.4444
A21: People First Bank | B21: 00130000000IW5dAAG | C21: Financial Services & Insurance | D21: 83 | E21: 28 | F21: 34 | G21: 21 | H21: 149 | I21: 87 | J21: 0.3373 | K21: 0.4096 | L21: 0.253 | M21: 0.5839 | N21: -- | O21: 2.4 | P21: 1.8 | Q21: 0.747 | R21: 0.4516
A22: Conagra | B22: 0010M00001SIcHPQA1 | C22: Retail/Consumer Goods | D22: 65 | E22: 27 | F22: 21 | G22: 17 | H22: 143 | I22: 95 | J22: 0.4154 | K22: 0.3231 | L22: 0.2615 | M22: 0.6643 | N22: -- | O22: 2.9791667 | P22: 2.2 | Q22: 0.7385 | R22: 0.5625
A23: Top Golf | C23: Retail/Consumer Goods | D23: 19 | E23: 4 | F23: 10 | G23: 5 | H23: 22 | I23: 8 | J23: 0.2105 | K23: 0.5263 | L23: 0.2632 | M23: 0.3636 | N23: -- | O23: 1.5714286 | P23: 1.1578947 | Q23: 0.7368 | R23: 0.2857
A24: Ameren | B24: 0010M00001UM4tHQAT | C24: Manufacturing, Auto, Energy | D24: 627 | E24: 169 | F24: 290 | G24: 168 | H24: 982 | I24: 523 | J24: 0.2695 | K24: 0.4625 | L24: 0.2679 | M24: 0.5326 | N24: -- | O24: 2.1394336 | P24: 1.5661882 | Q24: 0.7321 | R24: 0.3682
A25: American Builders & Contractors Supply Co. | B25: 0013y00001dW5muAAC | C25: Manufacturing, Auto, Energy | D25: 228 | E25: 61 | F25: 105 | G25: 62 | H25: 412 | I25: 246 | J25: 0.2675 | K25: 0.4605 | L25: 0.2719 | M25: 0.5971 | N25: -- | O25: 2.48 | P25: 1.81 | Q25: 0.7281 | R25: 0.3675
A26: saks | B26: 0013y00001cIoruAAC | C26: Retail/Consumer Goods | D26: 47 | E26: 8 | F26: 26 | G26: 13 | H26: 79 | I26: 45 | J26: 0.1702 | K26: 0.5532 | L26: 0.2766 | M26: 0.653 | N26: 0.5696 | O26: 2.32 | P26: 1.68 | Q26: 0.7234 | R26: 0.2353
A27: Weis Markets | B27: 00130000002xcHVAAY | C27: Retail/Consumer Goods | D27: 31 | E27: 12 | F27: 10 | G27: 9 | H27: 46 | I27: 24 | J27: 0.3871 | K27: 0.3226 | L27: 0.2903 | M27: 0.5217 | N27: -- | O27: 2.0909091 | P27: 1.483871 | Q27: 0.7097 | R27: 0.5455
A28: TransUnion LLC | B28: 00100000001eEnzAAE | C28: Financial Services & Insurance | D28: 215 | E28: 68 | F28: 79 | G28: 68 | H28: 378 | I28: 231 | J28: 0.3163 | K28: 0.3674 | L28: 0.3163 | M28: 0.5957 | N28: 0.6111 | O28: 2.57 | P28: 1.76 | Q28: 0.6837 | R28: 0.4626
A29: Mark Anthony Group | B29: 0013000000NRJqFAAX | C29: Retail/Consumer Goods | D29: 84 | E29: 24 | F29: 33 | G29: 27 | H29: 119 | I29: 62 | J29: 0.2857 | K29: 0.3929 | L29: 0.3214 | M29: 0.521 | N29: -- | O29: 2.0877193 | P29: 1.4166667 | Q29: 0.6786 | R29: 0.4211
A30: Inspira | B30: 0013000000M2AHDAA3 | C30: Financial Services & Insurance | D30: 58 | E30: 21 | F30: 18 | G30: 19 | H30: 109 | I30: 70 | J30: 0.3621 | K30: 0.3103 | L30: 0.3276 | M30: 0.5604 | N30: 0.6422 | O30: 2.79 | P30: 1.88 | Q30: 0.6724 | R30: 0.5385
A31: LogicMonitor | B31: 0013000000NRbGMAA1 | C31: Technology, Media, Telecomm | D31: 21 | E31: 2 | F31: 12 | G31: 7 | H31: 16 | I31: 2 | J31: 0.0952 | K31: 0.5714 | L31: 0.3333 | M31: 0.125 | N31: -- | O31: 1.1428571 | P31: 0.76190476 | Q31: 0.6667 | R31: 0.1429
A32: Orange Lake Country Club, Inc (Holiday Inn) | C32: Consumer and Business Services | D32: 82 | E32: 29 | F32: 25 | G32: 28 | H32: 175 | I32: 121 | J32: 0.3537 | K32: 0.3049 | L32: 0.3415 | M32: 0.6914 | N32: -- | O32: 3.24 | P32: 2.13 | Q32: 0.6585 | R32: 0.537
A33: NiSource | B33: 00130000003jhJJAAY | C33: Manufacturing, Auto, Energy | D33: 176 | E33: 20 | F33: 93 | G33: 63 | H33: 237 | I33: 124 | J33: 0.1136 | K33: 0.5284 | L33: 0.358 | M33: 0.5232 | N33: -- | O33: 2.0973451 | P33: 1.3465909 | Q33: 0.642 | R33: 0.177
A34: Cyberdine System | B34: 0010M00001U9tT6QAJ | C34: Manufacturing, Auto, Energy | D34: 94 | E34: 26 | F34: 34 | G34: 34 | H34: 173 | I34: 113 | J34: 0.2766 | K34: 0.3617 | L34: 0.3617 | M34: 0.6532 | N34: -- | O34: 2.88 | P34: 1.84 | Q34: 0.6383 | R34: 0.4333
A35: UBS Financial Services | B35: 00130000016gp7kAAA | C35: Financial Services & Insurance | D35: 117 | E35: 19 | F35: 55 | G35: 43 | H35: 196 | I35: 122 | J35: 0.1624 | K35: 0.4701 | L35: 0.3675 | M35: 0.6224 | N35: -- | O35: 2.65 | P35: 1.68 | Q35: 0.6325 | R35: 0.2568
A36: Burns and McDonnell Inc | C36: Consumer and Business Services | D36: 76 | E36: 20 | F36: 28 | G36: 28 | H36: 97 | I36: 49 | J36: 0.2632 | K36: 0.3684 | L36: 0.3684 | M36: 0.5052 | N36: -- | O36: 2.0208333 | P36: 1.2763158 | Q36: 0.6316 | R36: 0.4167
A37: Equifax | C37: Consumer and Business Services | D37: 143 | E37: 25 | F37: 63 | G37: 55 | H37: 212 | I37: 124 | J37: 0.1748 | K37: 0.4406 | L37: 0.3846 | M37: 0.5849 | N37: -- | O37: 2.4090909 | P37: 1.4825175 | Q37: 0.6154 | R37: 0.2841
A38: Sonoco | B38: 0013000000rneKjAAI | C38: Manufacturing, Auto, Energy | D38: 43 | E38: 12 | F38: 14 | G38: 17 | H38: 50 | I38: 24 | J38: 0.2791 | K38: 0.3256 | L38: 0.3953 | M38: 0.48 | O38: 1.9230769 | P38: 1.1627907 | Q38: 0.6047 | R38: 0.4615
A39: Solventum | B39: 0013000001JyXn0AAF | C39: Healthcare, Life Sciences | D39: 103 | E39: 21 | F39: 41 | G39: 41 | H39: 117 | I39: 55 | J39: 0.2039 | K39: 0.3981 | L39: 0.3981 | M39: 0.4701 | N39: -- | O39: 1.8870968 | P39: 1.1359223 | Q39: 0.6019 | R39: 0.3387
A40: Sobeys | C40: Canada | D40: 127 | E40: 27 | F40: 49 | G40: 51 | H40: 195 | I40: 119 | J40: 0.2126 | K40: 0.3858 | L40: 0.4016 | M40: 0.6103 | N40: -- | O40: 2.5657895 | P40: 1.5354331 | Q40: 0.5984 | R40: 0.3553
...

Sheet API Size
A1: {={"All"; SORT(UNIQUE('Helper Lists'!C2:C1000))}} -> All
A3: 1 - 30 APIs
A4: 101 - 200 APIs
A5: 201 - 400 APIs
A6: 31 - 60 APIs
A7: 400+ APIs
A8: 61 - 100 APIs

Sheet Helper Lists
A1: {={"All"; SORT(UNIQUE('Data Tab'!C2:C878))}} -> All | B1: {=SORT(UNIQUE('Data Tab'!A2:A878))} -> 3M Company | C1: {=IF(B1:B878="", "", LET(api, VLOOKUP(B1:B878, 'Data Tab'!A:D, 4, FALSE), IF(api="", "", IF(api<=30, "1 - 30 APIs", IF(api<=60, "31 - 60 APIs", IF(api<=100, "61 - 100 APIs", IF(api<=200, "101 - 200 APIs", IF(api<=400, "201 - 400 APIs", "400+ APIs"))))))))} -> 61 - 100 APIs
A2: Canada | B2: 7-Eleven (Australia) | C2: 31 - 60 APIs
A3: Consumer and Business Services | B3: AAA Automobile Club of Southern California | C3: 201 - 400 APIs
A4: Financial Services & Insurance | B4: AB Inbev | C4: 61 - 100 APIs
A5: Healthcare, Life Sciences | B5: AbbVie Inc. | C5: 101 - 200 APIs
A6: Manufacturing, Auto, Energy | B6: ABC Supply Co | C6: 201 - 400 APIs
A7: Public Sector | B7: ABSA Bank | C7: 201 - 400 APIs
A8: Retail/Consumer Goods | B8: Abu Dhabi Development Group (ADQ) | C8: 1 - 30 APIs
A9: Technology, Media, Telecomm | B9: Accent Group | C9: 1 - 30 APIs
A10: Travel, Transportation, & Hospitality | B10: Acolad | C10: 31 - 60 APIs
B11: Acrisure, LLC | C11: 1 - 30 APIs
B12: Adecco Group | C12: 31 - 60 APIs
B13: ADP | C13: 31 - 60 APIs
B14: AFL | C14: 61 - 100 APIs
B15: Aflac | C15: 101 - 200 APIs
B16: Agilent Technologies | C16: 1 - 30 APIs
B17: Akamai | C17: 101 - 200 APIs
B18: ALBIANT IT (BPCE) | C18: 31 - 60 APIs
B19: Allegis Group | C19: 201 - 400 APIs
B20: Alpargatas | C20: 1 - 30 APIs
B21: Alpiq Star Platform | C21: 1 - 30 APIs
B22: Ameren | C22: 400+ APIs
... B449: ZoomInfo | C449: 1 - 30 APIs
